<robot name="pi_robot">

    <link name="link1">
        <visual>
            <origin xyz="0 0 0" rpy="0 0 0"/>
            <geometry>
                <cylinder radius="1" length="0.2"/>
            </geometry>
            <material name="Cyan1">
                <color rgba="0 0.9 0.9 1.0"/>
            </material>
        </visual>
        <collision>
            <origin xyz="0 0 0" rpy="0 0 0"/>
            <geometry>
                <cylinder radius="0.5" length="0.2"/>
            </geometry>
        </collision>
        <inertial>
            <origin xyz="0 0 0" rpy="0 0 0"/>
            <mass value="100"/>
            <inertia
                ixx="0.1" ixy="0.0" ixz="0.0"
                iyy="0.1" iyz="0.0"
                izz="0.1"/>
        </inertial>
    </link>

    <link name="link2">
        <visual>
            <origin xyz="0 0 0.25" rpy="0 0 0"/>
            <geometry>
                <cylinder radius="0.3" length="0.3"/>
            </geometry>
            <material name="Black1">
                <color rgba="0.2 0.2 0.2 1.0"/>
            </material>
        </visual>
        <collision>
            <origin xyz="0 0 0.25" rpy="0 0 0"/>
            <geometry>
                <cylinder radius="0.3" length="0.3"/>
            </geometry>
        </collision>
        <inertial>
            <origin xyz="0 0 0" rpy="0 0 0"/>
            <mass value="0.5"/>
            <inertia
                ixx="0.1" ixy="0.0" ixz="0.0"
                iyy="0.1" iyz="0.0"
                izz="0.1"/>
        </inertial>
    </link>

     <joint name="base_link__link_01" type="revolute">
        <parent link="link1"/>
        <child link="link2"/>
            <origin xyz="0 0 0"/>
            <axis xyz="0 0 1"/>
            <limit effort="1000.0" lower="-3.14" upper="3.14" velocity="0.5"/>
            
    </joint>

    <link name="link3">
        <visual>
            <origin xyz="0 0 0.9" rpy="0 0 0"/>
            <geometry>
                <box size="0.2 0.2 1.5"/>
            </geometry>
            <material name="Cyan1">
                <color rgba="0 0.9 0.9 1.0"/>
            </material>
        </visual>
        <collision>
            <origin xyz="0 0 0.9" rpy="0 0 0"/>
            <geometry>
                <box size="0.2 0.2 1.5"/>
            </geometry>
        </collision>
        <inertial>
            <origin xyz="0 0 0" rpy="0 0 0"/>
            <mass value="0.5"/>
            <inertia
                ixx="0.1" ixy="0.0" ixz="0.0"
                iyy="0.1" iyz="0.0"
                izz="0.1"/>
        </inertial>
    </link>

    <joint name="base_link__link_02" type="fixed">
        <parent link="link2"/>
        <child link="link3"/>
        <origin xyz="0 0 0.001"/>
    </joint>

    <link name="link4">
        <visual>
            <origin xyz="0 0.15 1.55" rpy="1.57079633 0 0"/>
            <geometry>
                <cylinder radius="0.2" length="0.1"/>
            </geometry>
            <material name="Black1">
                <color rgba="0.2 0.2 0.2 1.0"/>
            </material>
        </visual>
        <collision>
            <origin xyz="0 0.15 1.55" rpy="1.57079633 0 0"/>
            <geometry>
                <cylinder radius="0.2" length="0.1"/>
            </geometry>
        </collision>
        <inertial>
            <origin xyz="0 0 0" rpy="0 0 0"/>
            <mass value="0.5"/>
            <inertia
                ixx="0.1" ixy="0.0" ixz="0.0"
                iyy="0.1" iyz="0.0"
                izz="0.1"/>
        </inertial>
    </link>

    <joint name="base_link__link_03" type="fixed">
        <parent link="link3"/>
        <child link="link4"/>
        <origin xyz="0 0 0.001"/>
    </joint>

    <link name="link5">
        <visual>
            <origin xyz="0 0.25 1.55" rpy="1.57079633 0 0"/>
            <geometry>
                <cylinder radius="0.2" length="0.1"/>
            </geometry>
            <material name="Black1">
                <color rgba="0.2 0.2 0.2 1.0"/>.25 2.65
            </material>
        </visual>
        <collision>
            <origin xyz="0 0.25 1.55" rpy="1.57079633 0 0"/>
            <geometry>
                <cylinder radius="0.2" length="0.1"/>
            </geometry>
        </collision>
        <inertial>
            <origin xyz="0 0 0" rpy="0 0 0"/>
            <mass value="0.5"/>
            <inertia
                ixx="0.1" ixy="0.0" ixz="0.0"
                iyy="0.1" iyz="0.0"
                izz="0.1"/>
        </inertial>
    </link>

    <joint name="base_link__link_04" type="revolute">
        <parent link="link4"/>
        <child link="link5"/>
            <origin xyz="0 0 1.55"/>
            <axis xyz="0 1 0"/>
            <limit effort="1000.0" lower="-3.14" upper="3.14" velocity="0.5"/>
    </joint>

    <link name="link6">
        <visual>
            <origin xyz="0 0.4 2.1" rpy="0 0 0"/>
            <geometry>
                <box size="0.2 0.2 1.3"/>
            </geometry>
            <material name="Cyan1">
                <color rgba="0 0.9 0.9 1.0"/>
            </material>
        </visual>
        <collision>
            <origin xyz="0 0.4 1.7" rpy="0 0 0"/>
            <geometry>
                <box size="0.2 0.2 1"/>
            </geometry>
        </collision>
        <inertial>
            <origin xyz="0 0 0" rpy="0 0 0"/>
            <mass value="0.5"/>
            <inertia
                ixx="0.1" ixy="0.0" ixz="0.0"
                iyy="0.1" iyz="0.0"
                izz="0.1"/>
        </inertial>
    </link>

    <joint name="base_link__link_05" type="fixed">
        <parent link="link5"/>
        <child link="link6"/>
        <origin xyz="0 0 0.001"/>
    </joint>

    <link name="link7">
        <visual>
            <origin xyz="0 0.25 2.65" rpy="1.57079633 0 0"/>
            <geometry>
                <cylinder radius="0.2" length="0.1"/>
            </geometry>
            <material name="Black1">
                <color rgba="0.2 0.2 0.2 1.0"/>
            </material>
        </visual>
        <collision>
            <origin xyz="0 0.25 2.65" rpy="1.57079633 0 0"/>
            <geometry>
                <cylinder radius="0.2" length="0.1"/>
            </geometry>
        </collision>
        <inertial>
            <origin xyz="0 0 0" rpy="0 0 0"/>
            <mass value="0.5"/>
            <inertia
                ixx="0.1" ixy="0.0" ixz="0.0"
                iyy="0.1" iyz="0.0"
                izz="0.1"/>
        </inertial>
    </link>

    <joint name="base_link__link_06" type="fixed">
        <parent link="link6"/>
        <child link="link7"/>
        <origin xyz="0 0 0.001"/>
    </joint>

    <link name="link8">
        <visual>
            <origin xyz="0 0.15 2.65" rpy="1.57079633 0 0"/>
            <geometry>
                <cylinder radius="0.2" length="0.1"/>
            </geometry>
            <material name="Black1">
                <color rgba="0.2 0.2 0.2 1.0"/>
            </material>
        </visual>
        <collision>
            <origin xyz="0 0.15 2.65" rpy="1.57079633 0 0"/>
            <geometry>
                <cylinder radius="0.2" length="0.1"/>
            </geometry>
        </collision>
        <inertial>
            <origin xyz="0 0 0" rpy="0 0 0"/>
            <mass value="0.5"/>
            <inertia
                ixx="0.1" ixy="0.0" ixz="0.0"
                iyy="0.1" iyz="0.0"
                izz="0.1"/>
        </inertial>
    </link>

    <joint name="base_link__link_07" type="revolute">
        <parent link="link7"/>
        <child link="link8"/>
            <origin xyz="0 0 2.65"/>
            <axis xyz="0 1 0"/>
            <limit effort="1000.0" lower="-3.14" upper="3.14" velocity="0.5"/>
    </joint>
    
    <link name="link9">
        <visual>
            <origin xyz="0 0 3.25" rpy="0 0 0"/>
            <geometry>
                <box size="0.2 0.2 1.5"/>
            </geometry>
            <material name="Cyan1">
                <color rgba="0 0.9 0.9 1.0"/>
            </material>
        </visual>
        <collision>
            <origin xyz="0 0 3.25" rpy="0 0 0"/>
            <geometry>
                <box size="0.2 0.2 1.5"/>
            </geometry>
        </collision>
        <inertial>
            <origin xyz="0 0 0" rpy="0 0 0"/>
            <mass value="0.5"/>
            <inertia
                ixx="0.1" ixy="0.0" ixz="0.0"
                iyy="0.1" iyz="0.0"
                izz="0.1"/>
        </inertial>
    </link>

    <joint name="base_link__link_08" type="fixed">
        <parent link="link8"/>
        <child link="link9"/>
        <origin xyz="0 0 0.001"/>
    </joint>

    <transmission name="tran1">
        <type>transmission_interface/SimpleTransmission</type>
        <joint name="base_link__link_01">
            <hardwareInterface>hardware_interface/EffortJointInterface</hardwareInterface>
        </joint>
        <actuator name="motor1">
            <hardwareInterface>hardware_interface/EffortJointInterface</hardwareInterface>
            <mechanicalReduction>1</mechanicalReduction>
        </actuator>
    </transmission>

    <gazebo>
        <plugin name="gazebo_ros_joint_state_publisher" filename="libgazebo_ros_joint_state_publisher.so">
            <joint_name>base_link__link_01</joint_name>
            <joint_name>base_link__link_02</joint_name>
            <joint_name>base_link__link_03</joint_name>
            <joint_name>base_link__link_04</joint_name>
            <joint_name>base_link__link_05</joint_name>
            <joint_name>base_link__link_06</joint_name>
            <joint_name>base_link__link_07</joint_name>
            <joint_name>base_link__link_08</joint_name>
        </plugin>
    </gazebo>

</robot>
