<?xml version="1.0"?>
<robot name="pi_robot" xmlns:xacro="http://www.ros.org/wiki/xacro">

    <xacro:include filename="$(find two_link_description)/xacro/two_link.gazebo"/>

	<link name="link1">
        <visual>
            <origin xyz="0 0 0.1" rpy="0 0 0"/>
            <geometry>
                <cylinder radius="0.7" length="0.2"/>
            </geometry>
            <material name="Cyan1">
                <color rgba="0 0.9 0.9 1.0"/>
            </material>
        </visual>
        <collision>
            <origin xyz="0 0 0.1" rpy="0 0 0"/>
            <geometry>
                <cylinder radius="0.7" length="0.2"/>
            </geometry>
        </collision>
        <inertial>
            <origin xyz="0 0 0.1" rpy="0 0 0"/>
            <mass value="100"/>
            <inertia
                ixx="0.1" ixy="0.0" ixz="0.0"
                iyy="0.1" iyz="0.0"
                izz="0.1"/>
        </inertial>
    </link>

    <link name="link2">
        <visual>
            <origin xyz="0 0 0.35" rpy="0 0 0"/>
            <geometry>
                <cylinder radius="0.4" length="0.3"/>
            </geometry>
            <material name="Black1">
                <color rgba="0.2 0.2 0.2 1.0"/>
            </material>
        </visual>
        <collision>
            <origin xyz="0 0 0.3" rpy="0 0 0"/>
            <geometry>
                <cylinder radius="0.4" length="0.3"/>
            </geometry>
        </collision>
        <inertial>
            <origin xyz="0 0 0.35" rpy="0 0 0"/>
            <mass value="0.5"/>
            <inertia
                ixx="0.1" ixy="0.0" ixz="0.0"
                iyy="0.1" iyz="0.0"
                izz="0.1"/>
        </inertial>
    </link>

     <joint name="rotate_around" type="revolute">
        <parent link="link1"/>
        <child link="link2"/>
            <origin xyz="0 0 0"/>
            <axis xyz="0 0 1"/>
            <limit effort="100" lower="-3.14" upper="3.14" velocity="0.5"/>
            
    </joint>

    <link name="link3">
        <visual>
            <origin xyz="0 0 1.24" rpy="0 0 0"/>
            <geometry>
                <box size="0.2 0.2 1.5"/>
            </geometry>
            <material name="Cyan1">
                <color rgba="0 0.9 0.9 1.0"/>
            </material>
        </visual>
        <collision>
            <origin xyz="0 0 1.24" rpy="0 0 0"/>
            <geometry>
                <box size="0.2 0.2 1.5"/>
            </geometry>
        </collision>
        <inertial>
            <origin xyz="0 0 1.24" rpy="0 0 0"/>
            <mass value="0.5"/>
            <inertia
                ixx="0.1" ixy="0.0" ixz="0.0"
                iyy="0.1" iyz="0.0"
                izz="0.1"/>
        </inertial>
    </link>

    <joint name="connect1" type="fixed">
        <parent link="link2"/>
        <child link="link3"/>
        <origin xyz="0 0 0.001"/>
    </joint>

    <link name="link4">
        <visual>
            <origin xyz="0 0.15 1.9" rpy="1.57 0 0"/>
            <geometry>
                <cylinder radius="0.2" length="0.1"/>
            </geometry>
            <material name="Black1">
                <color rgba="0.2 0.2 0.2 1.0"/>
            </material>
        </visual>
        <collision>
            <origin xyz="0 0.15 1.9" rpy="1.57 0 0"/>
            <geometry>
                <cylinder radius="0.2" length="0.1"/>
            </geometry>
        </collision>
        <inertial>
            <origin xyz="0 0.15 1.9" rpy="1.57 0 0"/>
            <mass value="0.5"/>
            <inertia
                ixx="0.1" ixy="0.0" ixz="0.0"
                iyy="0.1" iyz="0.0"
                izz="0.1"/>
        </inertial>
    </link>

    <joint name="connect2" type="fixed">
        <parent link="link3"/>
        <child link="link4"/>
        <origin xyz="0 0 0.001"/>
    </joint>

    <link name="link5">
        <visual>
            <origin xyz="0 0.25 0.0001" rpy="1.57 0 0"/>
            <geometry>
                <cylinder radius="0.2" length="0.1"/>
            </geometry>
            <material name="Black1">
                <color rgba="0.2 0.2 0.2 1.0"/>.25 2.65
            </material>
        </visual>
        <collision>
            <origin xyz="0 0.25 0.0001" rpy="1.57 0 0"/>
            <geometry>
                <cylinder radius="0.2" length="0.1"/>
            </geometry>
        </collision>
        <inertial>
            <origin xyz="0 0.25 0.0001" rpy="1.57 0 0"/>
            <mass value="0.5"/>
            <inertia
                ixx="0.1" ixy="0.0" ixz="0.0"
                iyy="0.1" iyz="0.0"
                izz="0.1"/>
        </inertial>
    </link>

    <joint name="move_arm1" type="revolute">
        <parent link="link4"/>
        <child link="link5"/>
            <origin xyz="0 0 1.9"/>
            <axis xyz="0 1 0"/>
            <limit effort="100" lower="-2" upper="2" velocity="0.5"/>
    </joint>

    <link name="link6">
        <visual>
            <origin xyz="0 0.4 0.6" rpy="0 0 0"/>
            <geometry>
                <box size="0.2 0.2 1.4"/>
            </geometry>
            <material name="Cyan1">
                <color rgba="0 0.9 0.9 1.0"/>
            </material>
        </visual>
        <collision>
            <origin xyz="0 0.4 0.6" rpy="0 0 0"/>
            <geometry>
                <box size="0.2 0.2 1.4"/>
            </geometry>
        </collision>
        <inertial>
            <origin xyz="0 0.4 0.6" rpy="0 0 0"/>
            <mass value="0.5"/>
            <inertia
                ixx="0.1" ixy="0.0" ixz="0.0"
                iyy="0.1" iyz="0.0"
                izz="0.1"/>
        </inertial>
    </link>

    <joint name="connect3" type="fixed">
        <parent link="link5"/>
        <child link="link6"/>
        <origin xyz="0 0 0.001"/>
    </joint>

    <link name="link7">
        <visual>
            <origin xyz="0 0.25 1.2" rpy="1.57 0 0"/>
            <geometry>
                <cylinder radius="0.2" length="0.1"/>
            </geometry>
            <material name="Black1">
                <color rgba="0.2 0.2 0.2 1.0"/>
            </material>
        </visual>
        <collision>
            <origin xyz="0 0.25 1.2" rpy="1.57 0 0"/>
            <geometry>
                <cylinder radius="0.2" length="0.1"/>
            </geometry>
        </collision>
        <inertial>
            <origin xyz="0 0.25 1.2" rpy="1.57 0 0"/>
            <mass value="0.5"/>
            <inertia
                ixx="0.1" ixy="0.0" ixz="0.0"
                iyy="0.1" iyz="0.0"
                izz="0.1"/>
        </inertial>
    </link>

    <joint name="connect4" type="fixed">
        <parent link="link6"/>
        <child link="link7"/>
        <origin xyz="0 0 0.001"/>
    </joint>

    <link name="link8">
        <visual>
            <origin xyz="0 0.15 0.0001" rpy="1.57 0 0"/>
            <geometry>
                <cylinder radius="0.2" length="0.1"/>
            </geometry>
            <material name="Black1">
                <color rgba="0.2 0.2 0.2 1.0"/>
            </material>
        </visual>
        <collision>
            <origin xyz="0 0.15 0.0001" rpy="1.57 0 0"/>
            <geometry>
                <cylinder radius="0.2" length="0.1"/>
            </geometry>
        </collision>
        <inertial>
            <origin xyz="0 0.15 0.0001" rpy="1.57 0 0"/>
            <mass value="0.5"/>
            <inertia
                ixx="0.1" ixy="0.0" ixz="0.0"
                iyy="0.1" iyz="0.0"
                izz="0.1"/>
        </inertial>
    </link>

    <joint name="move_arm2" type="revolute">
        <parent link="link7"/>
        <child link="link8"/>
            <origin xyz="0 0 1.2"/>
            <axis xyz="0 1 0"/>
            <limit effort="100" lower="-1" upper="1" velocity="0.5"/>
    </joint>
    
    <link name="link9">
        <visual>
            <origin xyz="0 0 0.7" rpy="0 0 0"/>
            <geometry>
                <box size="0.2 0.2 1.5"/>
            </geometry>
            <material name="Cyan1">
                <color rgba="0 0.9 0.9 1.0"/>
            </material>
        </visual>
        <collision>
            <origin xyz="0 0 0.7" rpy="0 0 0"/>
            <geometry>
                <box size="0.2 0.2 1.5"/>
            </geometry>
        </collision>
        <inertial>
            <origin xyz="0 0 0.7" rpy="0 0 0"/>
            <mass value="0.5"/>
            <inertia
                ixx="0.1" ixy="0.0" ixz="0.0"
                iyy="0.1" iyz="0.0"
                izz="0.1"/>
        </inertial>
    </link>

    <joint name="connect5" type="fixed">
        <parent link="link8"/>
        <child link="link9"/>
        <origin xyz="0 0 0.001"/>
    </joint>

    <link name="camera_link">
        <visual>
            <origin xyz="0 0 0" rpy="0 0 0"/>
            <geometry>
                <box size="0.05 0.05 0.05"/>
            </geometry>
            <material name="Black1">
                <color rgba="0.2 0.2 0.2 1.0"/>
            </material>
        </visual>
        <collision>
            <origin xyz="0 0 0.7" rpy="0 0 0"/>
            <geometry>
                <cylinder radius="0.05" length="0.04"/>
            </geometry>
        </collision>
        <inertial>
            <origin xyz="0 0 0.7" rpy="0 0 0"/>
            <mass value="0.5"/>
            <inertia
                ixx="0.1" ixy="0.0" ixz="0.0"
                iyy="0.1" iyz="0.0"
                izz="0.1"/>
        </inertial>
    </link>

    <joint name="camera_joint" type="fixed">
        <parent link="link9"/>
        <child link="camera_link"/>
        <origin xyz="0 0 1.47" rpy="0 -1.57 0"/>
    </joint>

    <link name="camera_optical_link"></link>

    <joint name="camera_optical_joint" type="fixed">
        <parent link="camera_link"/>
        <child link="camera_optical_link"/>
        <origin xyz="0 0 0.76" rpy="1.57 0 1.57"/>
    </joint>

    
        
</robot>